Workbook

Sheet Dashboard
B2: Total Tickets | C2: =KPI_Summary!B1 -> 500 | E2: SLA Compliance % | F2: =KPI_Summary!B6 -> 0.23 | H2: Avg Resolution Time (hrs) | I2: =KPI_Summary!B7 -> 24.30422 | K2: Avg CSAT | L2: =KPI_Summary!B9 -> 2.98
B4: Key Findings
B5: •Volume - Network, software, hardware, and access tickets are fairly evenly distributed, with Access tickets slightly highest in volume
B6: • SLA Compliance - Overall SLA compliance is low (~23%), indicating most tickets are not being resolved within SLA targets
B7: • High-priority tickets have the lowest SLA compliance (~17.6%), suggesting urgent issues are not being handled fast enough
B8: • Low-priority tickets show the highest SLA compliance (~29%), meaning less urgent work is handled more effectively
B9: • A large portion of tickets are either pending (159) or escalated (177), exceeding resolved tickets (164), indicating backlog pressure
B10: • The average resolution time (~24.3 hours) is relatively high compared to the first response time (~4.1 hours), suggesting delays occur after initial response
B12: Recommendations
B13: • Introduce stricter escalation workflows and faster assignment for critical and high-priority issues
B14: • Investigate why escalations (177) exceed resolved tickets and streamline resolution processes
B15: • Since first response is relatively quick but resolution is slow, focus on improving follow-up and ticket closure efficiency
B16: • Track SLA compliance in real time to quickly identify and address underperforming areas
B17: • Focus on categories or ticket types contributing to longer resolution times and escalations

Sheet KPI_Summary
A1: Total Tickets | B1: =ROWS(tblTickets[Ticket ID]) -> 500
A2: Resolved Tickets | B2: =COUNTIF(tblTickets[Status],"Resolved") -> 164
A3: Pending Tickets | B3: =COUNTIF(tblTickets[Status],"Pending") -> 159
A4: Escalated Tickets | B4: =COUNTIF(tblTickets[Status],"Escalated") -> 177
A5: SLA Met Tickets | B5: =COUNTIF(tblTickets[SLA Met],"Yes") -> 115
A6: SLA Compliance % | B6: =B5/B1 -> 0.23
A7: Avg Resolution Time (hrs) | B7: =AVERAGE(tblTickets[Actual Resolution Time (hrs)]) -> 24.30422
A8: Avg First Resolution Time (hrs) | B8: =AVERAGE(tblTickets[First Response Time (hrs)]) -> 4.0929
A9: Avg CSAT | B9: =AVERAGE(tblTickets[Customer Satisfaction]) -> 2.98
A10: Avg Tickets per Hour | B10: =AVERAGE(tblTime[Tickets per Hour]) -> 2.0092522
A11: Avg Utilization % | B11: =AVERAGE(tblTime[Utilization %]) -> 0.80537375

Sheet Pivot_Tables
A1: SLA Compliance by Priority - Count | F1: Count of SLA Met
A2: Count of SLA Met | B2: SLA Met
A3: Priority | B3: No | C3: Yes | D3: Grand Total | F3: Priority | G3: No | H3: Yes
A4: Critical | B4: 100 | C4: 27 | D4: 127 | F4: Critical | G4: =COUNTIFS(Support_Tickets!L:L,"No",Support_Tickets!D:D,Pivot_Tables!A4) -> 100 | H4: =COUNTIFS(Support_Tickets!L:L,"Yes",Support_Tickets!D:D,Pivot_Tables!A4) -> 27
A5: High | B5: 98 | C5: 21 | D5: 119 | F5: High | G5: =COUNTIFS(Support_Tickets!L:L,"No",Support_Tickets!D:D,Pivot_Tables!A5) -> 98 | H5: =COUNTIFS(Support_Tickets!L:L,"Yes",Support_Tickets!D:D,Pivot_Tables!A5) -> 21
A6: Low | B6: 87 | C6: 36 | D6: 123 | F6: Low | G6: =COUNTIFS(Support_Tickets!L:L,"No",Support_Tickets!D:D,Pivot_Tables!A6) -> 87 | H6: =COUNTIFS(Support_Tickets!L:L,"Yes",Support_Tickets!D:D,Pivot_Tables!A6) -> 36
A7: Medium | B7: 100 | C7: 31 | D7: 131 | F7: Medium | G7: =COUNTIFS(Support_Tickets!L:L,"No",Support_Tickets!D:D,Pivot_Tables!A7) -> 100 | H7: =COUNTIFS(Support_Tickets!L:L,"Yes",Support_Tickets!D:D,Pivot_Tables!A7) -> 31
A8: Grand Total | B8: 385 | C8: 115 | D8: 500
A11: SLA Compliance by Priority - Percentage
A12: Count of Tickets | B12: SLA Met | F12: SLA Compliance by Priority - Percentage
A13: Priority | B13: No | C13: Yes | D13: Grand Total | F13: Priority | G13: No | H13: Yes
A14: Critical | B14: 0.78740157 | C14: 0.21259843 | D14: 1 | F14: Critical | G14: =(G4/(G4+H4)) -> 0.78740157 | H14: =((H4/(G4+H4))) -> 0.21259843
A15: High | B15: 0.82352941 | C15: 0.17647059 | D15: 1 | F15: High | G15: =(G5/(G5+H5)) -> 0.82352941 | H15: =((H5/(G5+H5))) -> 0.17647059
A16: Low | B16: 0.70731707 | C16: 0.29268293 | D16: 1 | F16: Low | G16: =(G6/(G6+H6)) -> 0.70731707 | H16: =((H6/(G6+H6))) -> 0.29268293
A17: Medium | B17: 0.76335878 | C17: 0.23664122 | D17: 1 | F17: Medium | G17: =(G7/(G7+H7)) -> 0.76335878 | H17: =((H7/(G7+H7))) -> 0.23664122
A18: Grand Total | B18: 0.77 | C18: 0.23 | D18: 1
A22: Average Resolution Time by Category | F22: Average Resolution Time by Category
A23: Category | B23: Average of Actual Resolution Time (hrs) | F23: Category | G23: Average of Actual Resolution Time (hrs)
A24: Access | B24: 26.180677 | F24: Access | G24: =AVERAGEIFS(Support_Tickets!I:I,Support_Tickets!E:E,Pivot_Tables!A24) -> 26.180677
A25: Hardware | B25: 22.658898 | F25: Hardware | G25: =AVERAGEIFS(Support_Tickets!I:I,Support_Tickets!E:E,Pivot_Tables!A25) -> 22.658898
A26: Network | B26: 22.770763 | F26: Network | G26: =AVERAGEIFS(Support_Tickets!I:I,Support_Tickets!E:E,Pivot_Tables!A26) -> 22.770763
A27: Software | B27: 25.454508 | F27: Software | G27: =AVERAGEIFS(Support_Tickets!I:I,Support_Tickets!E:E,Pivot_Tables!A27) -> 25.454508
A28: Grand Total | B28: 24.30422
A32: Average Resolution Time by Agent | F32: Average Resolution Time by Agent
A33: Agent | B33: Average of Actual Resolution Time (hrs) | F33: Agent | G33: Average of Actual Resolution Time (hrs)
A34: Agent A | B34: 25.275818 | F34: Agent A | G34: =AVERAGEIFS(Support_Tickets!I:I,Support_Tickets!F:F,Pivot_Tables!A34) -> 25.275818
A35: Agent B | B35: 25.140909 | F35: Agent B | G35: =AVERAGEIFS(Support_Tickets!I:I,Support_Tickets!F:F,Pivot_Tables!A35) -> 25.140909
A36: Agent C | B36: 26.353441 | F36: Agent C | G36: =AVERAGEIFS(Support_Tickets!I:I,Support_Tickets!F:F,Pivot_Tables!A36) -> 26.353441
A37: Agent D | B37: 22.115313 | F37: Agent D | G37: =AVERAGEIFS(Support_Tickets!I:I,Support_Tickets!F:F,Pivot_Tables!A37) -> 22.115313
A38: Agent E | B38: 22.333297 | F38: Agent E | G38: =AVERAGEIFS(Support_Tickets!I:I,Support_Tickets!F:F,Pivot_Tables!A38) -> 22.333297
A39: Grand Total | B39: 24.30422
A43: CSAT by Agent | F43: CSAT by Agent
A44: Agent | B44: Average of Customer Satisfaction | F44: Agent | G44: Average of Customer Satisfaction
A45: Agent A | B45: 3.2 | F45: Agent A | G45: =AVERAGEIFS(Support_Tickets!K:K,Support_Tickets!F:F,Pivot_Tables!A45) -> 3.2
A46: Agent B | B46: 2.9181818 | F46: Agent B | G46: =AVERAGEIFS(Support_Tickets!K:K,Support_Tickets!F:F,Pivot_Tables!A46) -> 2.9181818
A47: Agent C | B47: 3.0107527 | F47: Agent C | G47: =AVERAGEIFS(Support_Tickets!K:K,Support_Tickets!F:F,Pivot_Tables!A47) -> 3.0107527
A48: Agent D | B48: 2.8020833 | F48: Agent D | G48: =AVERAGEIFS(Support_Tickets!K:K,Support_Tickets!F:F,Pivot_Tables!A48) -> 2.8020833
A49: Agent E | B49: 2.9450549 | F49: Agent E | G49: =AVERAGEIFS(Support_Tickets!K:K,Support_Tickets!F:F,Pivot_Tables!A49) -> 2.9450549
A50: Grand Total | B50: 2.98
A53: Tickets by Category | F53: Tickets by Category
...

Sheet Charts

Sheet --> Data

Sheet Agent_TimeSheets
A1: Agent Name | B1: Date | C1: Hours Worked | D1: Tickets Handled | E1: Idle Time (hrs) | F1: Overtime Hours | G1: Tickets per Hour | H1: Utilization % | I1: Productive Hours | J1: Experience Level | K1: Team | L1: City | M1: Gender | N1: First Response Time (hrs)
A2: Agent E | B2: 45739 | C2: 6.11 | D2: 14 | E2: 2.86 | F2: 0 | G2: =tblTime[[#This Row],[Tickets Handled]]/tblTime[[#This Row],[Hours Worked]] -> 2.2913257 | H2: =(tblTime[[#This Row],[Hours Worked]]-tblTime[[#This Row],[Idle Time (hrs)]])/tblTime[[#This Row],[Hours Worked]] -> 0.53191489 | I2: =tblTime[[#This Row],[Hours Worked]]-tblTime[[#This Row],[Idle Time (hrs)]] -> 3.25 | J2: =VLOOKUP(tblTime[[#This Row],[Agent Name]],tblAgents[[#All],[Agent Name]:[Experience Level]],2,FALSE) -> Junior | K2: =VLOOKUP(tblTime[[#This Row],[Agent Name]],Agent_Info!A:C,3,FALSE) -> Team 2 | L2: =VLOOKUP(tblTime[[#This Row],[Agent Name]],Agent_Info!A:D,4,FALSE) -> edison | M2: =VLOOKUP(tblTime[[#This Row],[Agent Name]],Agent_Info!$A:$E,5,FALSE) -> F | N2: =SUMIFS(Support_Tickets!J:J, Support_Tickets!B:B, tblTime[[#This Row],[Date]],Support_Tickets!F:F,tblTime[[#This Row],[Agent Name]]) -> 15.01
A3: Agent C | B3: 45692 | C3: 6.52 | D3: 13 | E3: 2.85 | F3: 0 | G3: =tblTime[[#This Row],[Tickets Handled]]/tblTime[[#This Row],[Hours Worked]] -> 1.993865 | H3: =(tblTime[[#This Row],[Hours Worked]]-tblTime[[#This Row],[Idle Time (hrs)]])/tblTime[[#This Row],[Hours Worked]] -> 0.56288344 | I3: =tblTime[[#This Row],[Hours Worked]]-tblTime[[#This Row],[Idle Time (hrs)]] -> 3.67 | J3: =VLOOKUP(tblTime[[#This Row],[Agent Name]],tblAgents[[#All],[Agent Name]:[Experience Level]],2,FALSE) -> Junior | K3: =VLOOKUP(tblTime[[#This Row],[Agent Name]],Agent_Info!A:C,3,FALSE) -> Team 1 | L3: =VLOOKUP(tblTime[[#This Row],[Agent Name]],Agent_Info!A:D,4,FALSE) -> richmond | M3: =VLOOKUP(tblTime[[#This Row],[Agent Name]],Agent_Info!$A:$E,5,FALSE) -> F | N3: =SUMIFS(Support_Tickets!J:J, Support_Tickets!B:B, tblTime[[#This Row],[Date]],Support_Tickets!F:F,tblTime[[#This Row],[Agent Name]]) -> 0
A4: Agent B | B4: 45681 | C4: 6.13 | D4: 23 | E4: 2.65 | F4: 0 | G4: =tblTime[[#This Row],[Tickets Handled]]/tblTime[[#This Row],[Hours Worked]] -> 3.7520392 | H4: =(tblTime[[#This Row],[Hours Worked]]-tblTime[[#This Row],[Idle Time (hrs)]])/tblTime[[#This Row],[Hours Worked]] -> 0.56769984 | I4: =tblTime[[#This Row],[Hours Worked]]-tblTime[[#This Row],[Idle Time (hrs)]] -> 3.48 | J4: =VLOOKUP(tblTime[[#This Row],[Agent Name]],tblAgents[[#All],[Agent Name]:[Experience Level]],2,FALSE) -> Junior | K4: =VLOOKUP(tblTime[[#This Row],[Agent Name]],Agent_Info!A:C,3,FALSE) -> Team 1 | L4: =VLOOKUP(tblTime[[#This Row],[Agent Name]],Agent_Info!A:D,4,FALSE) -> new york | M4: =VLOOKUP(tblTime[[#This Row],[Agent Name]],Agent_Info!$A:$E,5,FALSE) -> F | N4: =SUMIFS(Support_Tickets!J:J, Support_Tickets!B:B, tblTime[[#This Row],[Date]],Support_Tickets!F:F,tblTime[[#This Row],[Agent Name]]) -> 2.43
A5: Agent C | B5: 45693 | C5: 6.96 | D5: 23 | E5: 2.95 | F5: 0 | G5: =tblTime[[#This Row],[Tickets Handled]]/tblTime[[#This Row],[Hours Worked]] -> 3.3045977 | H5: =(tblTime[[#This Row],[Hours Worked]]-tblTime[[#This Row],[Idle Time (hrs)]])/tblTime[[#This Row],[Hours Worked]] -> 0.57614943 | I5: =tblTime[[#This Row],[Hours Worked]]-tblTime[[#This Row],[Idle Time (hrs)]] -> 4.01 | J5: =VLOOKUP(tblTime[[#This Row],[Agent Name]],tblAgents[[#All],[Agent Name]:[Experience Level]],2,FALSE) -> Junior | K5: =VLOOKUP(tblTime[[#This Row],[Agent Name]],Agent_Info!A:C,3,FALSE) -> Team 1 | L5: =VLOOKUP(tblTime[[#This Row],[Agent Name]],Agent_Info!A:D,4,FALSE) -> richmond | M5: =VLOOKUP(tblTime[[#This Row],[Agent Name]],Agent_Info!$A:$E,5,FALSE) -> F | N5: =SUMIFS(Support_Tickets!J:J, Support_Tickets!B:B, tblTime[[#This Row],[Date]],Support_Tickets!F:F,tblTime[[#This Row],[Agent Name]]) -> 4.66
A6: Agent C | B6: 45688 | C6: 6.79 | D6: 22 | E6: 2.7 | F6: 0 | G6: =tblTime[[#This Row],[Tickets Handled]]/tblTime[[#This Row],[Hours Worked]] -> 3.2400589 | H6: =(tblTime[[#This Row],[Hours Worked]]-tblTime[[#This Row],[Idle Time (hrs)]])/tblTime[[#This Row],[Hours Worked]] -> 0.60235641 | I6: =tblTime[[#This Row],[Hours Worked]]-tblTime[[#This Row],[Idle Time (hrs)]] -> 4.09 | J6: =VLOOKUP(tblTime[[#This Row],[Agent Name]],tblAgents[[#All],[Agent Name]:[Experience Level]],2,FALSE) -> Junior | K6: =VLOOKUP(tblTime[[#This Row],[Agent Name]],Agent_Info!A:C,3,FALSE) -> Team 1 | L6: =VLOOKUP(tblTime[[#This Row],[Agent Name]],Agent_Info!A:D,4,FALSE) -> richmond | M6: =VLOOKUP(tblTime[[#This Row],[Agent Name]],Agent_Info!$A:$E,5,FALSE) -> F | N6: =SUMIFS(Support_Tickets!J:J, Support_Tickets!B:B, tblTime[[#This Row],[Date]],Support_Tickets!F:F,tblTime[[#This Row],[Agent Name]]) -> 12.35
A7: Agent A | B7: 45702 | C7: 6.24 | D7: 9 | E7: 2.48 | F7: 0 | G7: =tblTime[[#This Row],[Tickets Handled]]/tblTime[[#This Row],[Hours Worked]] -> 1.4423077 | H7: =(tblTime[[#This Row],[Hours Worked]]-tblTime[[#This Row],[Idle Time (hrs)]])/tblTime[[#This Row],[Hours Worked]] -> 0.6025641 | I7: =tblTime[[#This Row],[Hours Worked]]-tblTime[[#This Row],[Idle Time (hrs)]] -> 3.76 | J7: =VLOOKUP(tblTime[[#This Row],[Agent Name]],tblAgents[[#All],[Agent Name]:[Experience Level]],2,FALSE) -> Mid | K7: =VLOOKUP(tblTime[[#This Row],[Agent Name]],Agent_Info!A:C,3,FALSE) -> Team 2 | L7: =VLOOKUP(tblTime[[#This Row],[Agent Name]],Agent_Info!A:D,4,FALSE) -> dallas | M7: =VLOOKUP(tblTime[[#This Row],[Agent Name]],Agent_Info!$A:$E,5,FALSE) -> M | N7: =SUMIFS(Support_Tickets!J:J, Support_Tickets!B:B, tblTime[[#This Row],[Date]],Support_Tickets!F:F,tblTime[[#This Row],[Agent Name]]) -> 18.52
A8: Agent D | B8: 45738 | C8: 7.29 | D8: 23 | E8: 2.88 | F8: 0 | G8: =tblTime[[#This Row],[Tickets Handled]]/tblTime[[#This Row],[Hours Worked]] -> 3.1550069 | H8: =(tblTime[[#This Row],[Hours Worked]]-tblTime[[#This Row],[Idle Time (hrs)]])/tblTime[[#This Row],[Hours Worked]] -> 0.60493827 | I8: =tblTime[[#This Row],[Hours Worked]]-tblTime[[#This Row],[Idle Time (hrs)]] -> 4.41 | J8: =VLOOKUP(tblTime[[#This Row],[Agent Name]],tblAgents[[#All],[Agent Name]:[Experience Level]],2,FALSE) -> Senior | K8: =VLOOKUP(tblTime[[#This Row],[Agent Name]],Agent_Info!A:C,3,FALSE) -> Team 2 | L8: =VLOOKUP(tblTime[[#This Row],[Agent Name]],Agent_Info!A:D,4,FALSE) -> hillsborough | M8: =VLOOKUP(tblTime[[#This Row],[Agent Name]],Agent_Info!$A:$E,5,FALSE) -> M | N8: =SUMIFS(Support_Tickets!J:J, Support_Tickets!B:B, tblTime[[#This Row],[Date]],Support_Tickets!F:F,tblTime[[#This Row],[Agent Name]]) -> 20.18
A9: Agent B | B9: 45696 | C9: 6.9 | D9: 19 | E9: 2.67 | F9: 0 | G9: =tblTime[[#This Row],[Tickets Handled]]/tblTime[[#This Row],[Hours Worked]] -> 2.7536232 | H9: =(tblTime[[#This Row],[Hours Worked]]-tblTime[[#This Row],[Idle Time (hrs)]])/tblTime[[#This Row],[Hours Worked]] -> 0.61304348 | I9: =tblTime[[#This Row],[Hours Worked]]-tblTime[[#This Row],[Idle Time (hrs)]] -> 4.23 | J9: =VLOOKUP(tblTime[[#This Row],[Agent Name]],tblAgents[[#All],[Agent Name]:[Experience Level]],2,FALSE) -> Junior | K9: =VLOOKUP(tblTime[[#This Row],[Agent Name]],Agent_Info!A:C,3,FALSE) -> Team 1 | L9: =VLOOKUP(tblTime[[#This Row],[Agent Name]],Agent_Info!A:D,4,FALSE) -> new york | M9: =VLOOKUP(tblTime[[#This Row],[Agent Name]],Agent_Info!$A:$E,5,FALSE) -> F | N9: =SUMIFS(Support_Tickets!J:J, Support_Tickets!B:B, tblTime[[#This Row],[Date]],Support_Tickets!F:F,tblTime[[#This Row],[Agent Name]]) -> 0
A10: Agent B | B10: 45679 | C10: 6.2 | D10: 5 | E10: 2.38 | F10: 0 | G10: =tblTime[[#This Row],[Tickets Handled]]/tblTime[[#This Row],[Hours Worked]] -> 0.80645161 | H10: =(tblTime[[#This Row],[Hours Worked]]-tblTime[[#This Row],[Idle Time (hrs)]])/tblTime[[#This Row],[Hours Worked]] -> 0.61612903 | I10: =tblTime[[#This Row],[Hours Worked]]-tblTime[[#This Row],[Idle Time (hrs)]] -> 3.82 | J10: =VLOOKUP(tblTime[[#This Row],[Agent Name]],tblAgents[[#All],[Agent Name]:[Experience Level]],2,FALSE) -> Junior | K10: =VLOOKUP(tblTime[[#This Row],[Agent Name]],Agent_Info!A:C,3,FALSE) -> Team 1 | L10: =VLOOKUP(tblTime[[#This Row],[Agent Name]],Agent_Info!A:D,4,FALSE) -> new york | M10: =VLOOKUP(tblTime[[#This Row],[Agent Name]],Agent_Info!$A:$E,5,FALSE) -> F | N10: =SUMIFS(Support_Tickets!J:J, Support_Tickets!B:B, tblTime[[#This Row],[Date]],Support_Tickets!F:F,tblTime[[#This Row],[Agent Name]]) -> 1.09
A11: Agent D | B11: 45721 | C11: 7.09 | D11: 18 | E11: 2.7 | F11: 0 | G11: =tblTime[[#This Row],[Tickets Handled]]/tblTime[[#This Row],[Hours Worked]] -> 2.538787 | H11: =(tblTime[[#This Row],[Hours Worked]]-tblTime[[#This Row],[Idle Time (hrs)]])/tblTime[[#This Row],[Hours Worked]] -> 0.61918195 | I11: =tblTime[[#This Row],[Hours Worked]]-tblTime[[#This Row],[Idle Time (hrs)]] -> 4.39 | J11: =VLOOKUP(tblTime[[#This Row],[Agent Name]],tblAgents[[#All],[Agent Name]:[Experience Level]],2,FALSE) -> Senior | K11: =VLOOKUP(tblTime[[#This Row],[Agent Name]],Agent_Info!A:C,3,FALSE) -> Team 2 | L11: =VLOOKUP(tblTime[[#This Row],[Agent Name]],Agent_Info!A:D,4,FALSE) -> hillsborough | M11: =VLOOKUP(tblTime[[#This Row],[Agent Name]],Agent_Info!$A:$E,5,FALSE) -> M | N11: =SUMIFS(Support_Tickets!J:J, Support_Tickets!B:B, tblTime[[#This Row],[Date]],Support_Tickets!F:F,tblTime[[#This Row],[Agent Name]]) -> 7.66
A12: Agent E | B12: 45698 | C12: 7.89 | D12: 8 | E12: 2.96 | F12: 0 | G12: =tblTime[[#This Row],[Tickets Handled]]/tblTime[[#This Row],[Hours Worked]] -> 1.0139417 | H12: =(tblTime[[#This Row],[Hours Worked]]-tblTime[[#This Row],[Idle Time (hrs)]])/tblTime[[#This Row],[Hours Worked]] -> 0.62484157 | I12: =tblTime[[#This Row],[Hours Worked]]-tblTime[[#This Row],[Idle Time (hrs)]] -> 4.93 | J12: =VLOOKUP(tblTime[[#This Row],[Agent Name]],tblAgents[[#All],[Agent Name]:[Experience Level]],2,FALSE) -> Junior | K12: =VLOOKUP(tblTime[[#This Row],[Agent Name]],Agent_Info!A:C,3,FALSE) -> Team 2 | L12: =VLOOKUP(tblTime[[#This Row],[Agent Name]],Agent_Info!A:D,4,FALSE) -> edison | M12: =VLOOKUP(tblTime[[#This Row],[Agent Name]],Agent_Info!$A:$E,5,FALSE) -> F | N12: =SUMIFS(Support_Tickets!J:J, Support_Tickets!B:B, tblTime[[#This Row],[Date]],Support_Tickets!F:F,tblTime[[#This Row],[Agent Name]]) -> 0
A13: Agent C | B13: 45673 | C13: 6.81 | D13: 14 | E13: 2.54 | F13: 0 | G13: =tblTime[[#This Row],[Tickets Handled]]/tblTime[[#This Row],[Hours Worked]] -> 2.0558003 | H13: =(tblTime[[#This Row],[Hours Worked]]-tblTime[[#This Row],[Idle Time (hrs)]])/tblTime[[#This Row],[Hours Worked]] -> 0.62701909 | I13: =tblTime[[#This Row],[Hours Worked]]-tblTime[[#This Row],[Idle Time (hrs)]] -> 4.27 | J13: =VLOOKUP(tblTime[[#This Row],[Agent Name]],tblAgents[[#All],[Agent Name]:[Experience Level]],2,FALSE) -> Junior | K13: =VLOOKUP(tblTime[[#This Row],[Agent Name]],Agent_Info!A:C,3,FALSE) -> Team 1 | L13: =VLOOKUP(tblTime[[#This Row],[Agent Name]],Agent_Info!A:D,4,FALSE) -> richmond | M13: =VLOOKUP(tblTime[[#This Row],[Agent Name]],Agent_Info!$A:$E,5,FALSE) -> F | N13: =SUMIFS(Support_Tickets!J:J, Support_Tickets!B:B, tblTime[[#This Row],[Date]],Support_Tickets!F:F,tblTime[[#This Row],[Agent Name]]) -> 2.91
... A201: Agent D | B201: 45747 | C201: 8.96 | D201: 13 | E201: 0.04 | F201: 0.96 | G201: =tblTime[[#This Row],[Tickets Handled]]/tblTime[[#This Row],[Hours Worked]] -> 1.4508929 | H201: =(tblTime[[#This Row],[Hours Worked]]-tblTime[[#This Row],[Idle Time (hrs)]])/tblTime[[#This Row],[Hours Worked]] -> 0.99553571 | I201: =tblTime[[#This Row],[Hours Worked]]-tblTime[[#This Row],[Idle Time (hrs)]] -> 8.92 | J201: =VLOOKUP(tblTime[[#This Row],[Agent Name]],tblAgents[[#All],[Agent Name]:[Experience Level]],2,FALSE) -> Senior | K201: =VLOOKUP(tblTime[[#This Row],[Agent Name]],Agent_Info!A:C,3,FALSE) -> Team 2 | L201: =VLOOKUP(tblTime[[#This Row],[Agent Name]],Agent_Info!A:D,4,FALSE) -> hillsborough | M201: =VLOOKUP(tblTime[[#This Row],[Agent Name]],Agent_Info!$A:$E,5,FALSE) -> M | N201: =SUMIFS(Support_Tickets!J:J, Support_Tickets!B:B, tblTime[[#This Row],[Date]],Support_Tickets!F:F,tblTime[[#This Row],[Agent Name]]) -> 2.08

Sheet Support_Tickets
A1: Ticket ID | B1: Created Date | C1: Resolved Date | D1: Priority | E1: Category | F1: Assigned Agent | G1: Status | H1: SLA Target (hrs) | I1: Actual Resolution Time (hrs) | J1: First Response Time (hrs) | K1: Customer Satisfaction | L1: SLA Met | M1: Ticket Age (hrs) | N1: CSAT Group
A2: T0137 | B2: 45661 | C2: 45661.082 | D2: Low | E2: Software | F2: Agent E | G2: Pending | H2: 4 | I2: 1.97 | J2: 7.23 | K2: 1 | L2: =IF(tblTickets[[#This Row],[SLA Target (hrs)]]>=tblTickets[[#This Row],[Actual Resolution Time (hrs)]],"Yes","No") -> Yes | M2: =(tblTickets[[#This Row],[Resolved Date]]-tblTickets[[#This Row],[Created Date]])*24 -> 1.97 | N2: =IF(tblTickets[[#This Row],[Customer Satisfaction]]>=4,"Satisfied",IF(tblTickets[[#This Row],[Customer Satisfaction]]=3,"Neutral","Dissatisfied")) -> Dissatisfied
A3: T0408 | B3: 45679 | C3: 45679.097 | D3: Critical | E3: Network | F3: Agent E | G3: Escalated | H3: 24 | I3: 2.32 | J3: 6.17 | K3: 1 | L3: =IF(tblTickets[[#This Row],[SLA Target (hrs)]]>=tblTickets[[#This Row],[Actual Resolution Time (hrs)]],"Yes","No") -> Yes | M3: =(tblTickets[[#This Row],[Resolved Date]]-tblTickets[[#This Row],[Created Date]])*24 -> 2.32 | N3: =IF(tblTickets[[#This Row],[Customer Satisfaction]]>=4,"Satisfied",IF(tblTickets[[#This Row],[Customer Satisfaction]]=3,"Neutral","Dissatisfied")) -> Dissatisfied
A4: T0181 | B4: 45739 | C4: 45739.097 | D4: High | E4: Hardware | F4: Agent E | G4: Resolved | H4: 24 | I4: 2.33 | J4: 5.36 | K4: 1 | L4: =IF(tblTickets[[#This Row],[SLA Target (hrs)]]>=tblTickets[[#This Row],[Actual Resolution Time (hrs)]],"Yes","No") -> Yes | M4: =(tblTickets[[#This Row],[Resolved Date]]-tblTickets[[#This Row],[Created Date]])*24 -> 2.33 | N4: =IF(tblTickets[[#This Row],[Customer Satisfaction]]>=4,"Satisfied",IF(tblTickets[[#This Row],[Customer Satisfaction]]=3,"Neutral","Dissatisfied")) -> Dissatisfied
A5: T0171 | B5: 45734 | C5: 45734.106 | D5: Low | E5: Software | F5: Agent E | G5: Pending | H5: 24 | I5: 2.54 | J5: 0.74 | K5: 1 | L5: =IF(tblTickets[[#This Row],[SLA Target (hrs)]]>=tblTickets[[#This Row],[Actual Resolution Time (hrs)]],"Yes","No") -> Yes | M5: =(tblTickets[[#This Row],[Resolved Date]]-tblTickets[[#This Row],[Created Date]])*24 -> 2.54 | N5: =IF(tblTickets[[#This Row],[Customer Satisfaction]]>=4,"Satisfied",IF(tblTickets[[#This Row],[Customer Satisfaction]]=3,"Neutral","Dissatisfied")) -> Dissatisfied
A6: T0102 | B6: 45660 | C6: 45660.132 | D6: Low | E6: Network | F6: Agent D | G6: Pending | H6: 4 | I6: 3.18 | J6: 2.56 | K6: 1 | L6: =IF(tblTickets[[#This Row],[SLA Target (hrs)]]>=tblTickets[[#This Row],[Actual Resolution Time (hrs)]],"Yes","No") -> Yes | M6: =(tblTickets[[#This Row],[Resolved Date]]-tblTickets[[#This Row],[Created Date]])*24 -> 3.18 | N6: =IF(tblTickets[[#This Row],[Customer Satisfaction]]>=4,"Satisfied",IF(tblTickets[[#This Row],[Customer Satisfaction]]=3,"Neutral","Dissatisfied")) -> Dissatisfied
A7: T0468 | B7: 45743 | C7: 45743.173 | D7: Medium | E7: Network | F7: Agent B | G7: Pending | H7: 24 | I7: 4.15 | J7: 7.43 | K7: 1 | L7: =IF(tblTickets[[#This Row],[SLA Target (hrs)]]>=tblTickets[[#This Row],[Actual Resolution Time (hrs)]],"Yes","No") -> Yes | M7: =(tblTickets[[#This Row],[Resolved Date]]-tblTickets[[#This Row],[Created Date]])*24 -> 4.15 | N7: =IF(tblTickets[[#This Row],[Customer Satisfaction]]>=4,"Satisfied",IF(tblTickets[[#This Row],[Customer Satisfaction]]=3,"Neutral","Dissatisfied")) -> Dissatisfied
A8: T0333 | B8: 45729 | C8: 45729.175 | D8: High | E8: Software | F8: Agent C | G8: Escalated | H8: 24 | I8: 4.19 | J8: 1.73 | K8: 1 | L8: =IF(tblTickets[[#This Row],[SLA Target (hrs)]]>=tblTickets[[#This Row],[Actual Resolution Time (hrs)]],"Yes","No") -> Yes | M8: =(tblTickets[[#This Row],[Resolved Date]]-tblTickets[[#This Row],[Created Date]])*24 -> 4.19 | N8: =IF(tblTickets[[#This Row],[Customer Satisfaction]]>=4,"Satisfied",IF(tblTickets[[#This Row],[Customer Satisfaction]]=3,"Neutral","Dissatisfied")) -> Dissatisfied
A9: T0081 | B9: 45692 | C9: 45692.181 | D9: Critical | E9: Hardware | F9: Agent D | G9: Resolved | H9: 24 | I9: 4.35 | J9: 2.78 | K9: 1 | L9: =IF(tblTickets[[#This Row],[SLA Target (hrs)]]>=tblTickets[[#This Row],[Actual Resolution Time (hrs)]],"Yes","No") -> Yes | M9: =(tblTickets[[#This Row],[Resolved Date]]-tblTickets[[#This Row],[Created Date]])*24 -> 4.35 | N9: =IF(tblTickets[[#This Row],[Customer Satisfaction]]>=4,"Satisfied",IF(tblTickets[[#This Row],[Customer Satisfaction]]=3,"Neutral","Dissatisfied")) -> Dissatisfied
A10: T0046 | B10: 45687 | C10: 45687.188 | D10: Critical | E10: Hardware | F10: Agent A | G10: Resolved | H10: 8 | I10: 4.51 | J10: 7.12 | K10: 1 | L10: =IF(tblTickets[[#This Row],[SLA Target (hrs)]]>=tblTickets[[#This Row],[Actual Resolution Time (hrs)]],"Yes","No") -> Yes | M10: =(tblTickets[[#This Row],[Resolved Date]]-tblTickets[[#This Row],[Created Date]])*24 -> 4.51 | N10: =IF(tblTickets[[#This Row],[Customer Satisfaction]]>=4,"Satisfied",IF(tblTickets[[#This Row],[Customer Satisfaction]]=3,"Neutral","Dissatisfied")) -> Dissatisfied
A11: T0036 | B11: 45682 | C11: 45682.201 | D11: Critical | E11: Network | F11: Agent B | G11: Pending | H11: 8 | I11: 4.82 | J11: 7.53 | K11: 1 | L11: =IF(tblTickets[[#This Row],[SLA Target (hrs)]]>=tblTickets[[#This Row],[Actual Resolution Time (hrs)]],"Yes","No") -> Yes | M11: =(tblTickets[[#This Row],[Resolved Date]]-tblTickets[[#This Row],[Created Date]])*24 -> 4.82 | N11: =IF(tblTickets[[#This Row],[Customer Satisfaction]]>=4,"Satisfied",IF(tblTickets[[#This Row],[Customer Satisfaction]]=3,"Neutral","Dissatisfied")) -> Dissatisfied
A12: T0041 | B12: 45683 | C12: 45683.305 | D12: Medium | E12: Software | F12: Agent D | G12: Pending | H12: 24 | I12: 7.31 | J12: 4.74 | K12: 1 | L12: =IF(tblTickets[[#This Row],[SLA Target (hrs)]]>=tblTickets[[#This Row],[Actual Resolution Time (hrs)]],"Yes","No") -> Yes | M12: =(tblTickets[[#This Row],[Resolved Date]]-tblTickets[[#This Row],[Created Date]])*24 -> 7.31 | N12: =IF(tblTickets[[#This Row],[Customer Satisfaction]]>=4,"Satisfied",IF(tblTickets[[#This Row],[Customer Satisfaction]]=3,"Neutral","Dissatisfied")) -> Dissatisfied
A13: T0337 | B13: 45665 | C13: 45665.4 | D13: Low | E13: Access | F13: Agent B | G13: Resolved | H13: 24 | I13: 9.61 | J13: 4.91 | K13: 1 | L13: =IF(tblTickets[[#This Row],[SLA Target (hrs)]]>=tblTickets[[#This Row],[Actual Resolution Time (hrs)]],"Yes","No") -> Yes | M13: =(tblTickets[[#This Row],[Resolved Date]]-tblTickets[[#This Row],[Created Date]])*24 -> 9.61 | N13: =IF(tblTickets[[#This Row],[Customer Satisfaction]]>=4,"Satisfied",IF(tblTickets[[#This Row],[Customer Satisfaction]]=3,"Neutral","Dissatisfied")) -> Dissatisfied
... A501: T0278 | B501: 45663 | C501: 45664.454 | D501: High | E501: Access | F501: Agent D | G501: Pending | H501: 4 | I501: 34.89 | J501: 5.72 | K501: 5 | L501: =IF(tblTickets[[#This Row],[SLA Target (hrs)]]>=tblTickets[[#This Row],[Actual Resolution Time (hrs)]],"Yes","No") -> No | M501: =(tblTickets[[#This Row],[Resolved Date]]-tblTickets[[#This Row],[Created Date]])*24 -> 34.89 | N501: =IF(tblTickets[[#This Row],[Customer Satisfaction]]>=4,"Satisfied",IF(tblTickets[[#This Row],[Customer Satisfaction]]=3,"Neutral","Dissatisfied")) -> Satisfied

Sheet Agent_Info
A1: Agent Name | B1: Experience Level | C1: Team | D1: City | E1: Gender | F1: tickets handled | G1: Actual Resolution Time (hrs) | H1: years worked
A2: Agent A | B2: Mid | C2: Team 2 | D2: dallas | E2: M | F2: =SUMIFS(Agent_TimeSheets!D:D, Agent_TimeSheets!A:A, tblAgents[[#This Row],[Agent Name]]) -> 525 | G2: =SUMIFS(Support_Tickets!I:I, Support_Tickets!F:F, tblAgents[[#This Row],[Agent Name]]) -> 2780.34 | H2: 2
A3: Agent B | B3: Junior | C3: Team 1 | D3: new york | E3: F | F3: =SUMIFS(Agent_TimeSheets!D:D, Agent_TimeSheets!A:A, tblAgents[[#This Row],[Agent Name]]) -> 631 | G3: =SUMIFS(Support_Tickets!I:I, Support_Tickets!F:F, tblAgents[[#This Row],[Agent Name]]) -> 2765.5 | H3: 4
A4: Agent C | B4: Junior | C4: Team 1 | D4: richmond | E4: F | F4: =SUMIFS(Agent_TimeSheets!D:D, Agent_TimeSheets!A:A, tblAgents[[#This Row],[Agent Name]]) -> 742 | G4: =SUMIFS(Support_Tickets!I:I, Support_Tickets!F:F, tblAgents[[#This Row],[Agent Name]]) -> 2450.87 | H4: 10
A5: Agent D | B5: Senior | C5: Team 2 | D5: hillsborough | E5: M | F5: =SUMIFS(Agent_TimeSheets!D:D, Agent_TimeSheets!A:A, tblAgents[[#This Row],[Agent Name]]) -> 801 | G5: =SUMIFS(Support_Tickets!I:I, Support_Tickets!F:F, tblAgents[[#This Row],[Agent Name]]) -> 2123.07 | H5: 3
A6: Agent E | B6: Junior | C6: Team 2 | D6: edison | E6: F | F6: =SUMIFS(Agent_TimeSheets!D:D, Agent_TimeSheets!A:A, tblAgents[[#This Row],[Agent Name]]) -> 444 | G6: =SUMIFS(Support_Tickets!I:I, Support_Tickets!F:F, tblAgents[[#This Row],[Agent Name]]) -> 2032.33 | H6: 5
